Workbook

Sheet README
B5: FIFA World Cup Analytics – Excel Business Intelligence Project
B11: OVERVIEW | K11: BUSINESS OBJECTIVE
B12: This project analyzes FIFA World Cup data from 1930 to 2026 using Microsoft Excel. The objective is not limited to visualizing historical football statistics. The workbook demonstrates a complete Business Intelligence workflow, including: source data exploration; data quality assessment; duplicate detection; data cleaning and standardization; KPI design; statistical analysis; interactive dashboard development; team comparison; indicative match probability modeling. The project was developed as part of a transition toward a Business Intelligence and Data Analyst career. | K12: The dashboard was designed as an executive analytical tool for exploring the history and evolution of the FIFA World Cup. The analysis addresses questions such as: Which national teams have achieved the strongest historical performances? Which teams have won the most FIFA World Cup titles? Which teams demonstrate the strongest offensive and defensive performance? How has the number of goals per match evolved over time? Which teams have the highest historical win rates? How frequently have matches been decided after extra time or by penalty shootouts? How do two selected national teams compare? What match outcome is suggested by their historical performance and recent form?
B33: DATASET | K33: WORKBOOK STRUCTURE
B34: The project uses data derived from The Ultimate FIFA World Cup Dataset (1930–2026), obtained from Kaggle. The workbook includes four source datasets: - Match results (1930–2026) - Penalty shootouts (1982 to 2026) - 2026 squads - 2026 teams summaries | K34: - README Presents the business objective, methodology, workbook structure and main limitations. - DATA_DICTIONNAIRE Documents the source datasets, fields, data types, nullability and examples. - KPI_DICTIONNAIRE Documents the business indicators, calculation principles, interpretation rules and data sources. - DATA_BRUT Contains the original imported datasets without transformation. - DATA_QUALITE Contains the quality control process, including: duplicate detection; country-name validation; character-encoding controls; numerical type checks; tournament-stage normalization; match-score verification; match-count reconciliation; correction mapping tables. | P34: -DATA_CLEANED Contains the standardized datasets used for analysis and dashboard calculations. - CALCULES Contains intermediate calculations and team-level metrics, including: (non-exhaustive) offensive score; defensive score; global performance score; stage reached; World Cup titles. - RESUME Provides a consolidated historical overview by tournament edition. - DASHBOARD Provides the interactive analytical interface, including: tournament-level KPIs; historical evolution charts; an interactive team comparison section; indicative match-outcome probabilities.
B55: DATA QUALITY PROCESS | K55: KEY PERFORMANCE INIDICATORS
B56: The data preparation process follows several stages: - preservation of the original source data; - identification of duplicate match records; - standardization of country and team names; - correction of character-encoding issues; - conversion of numerical fields; - normalization of tournament stages; - verification of goals and match winners; - reconciliation of the number of matches by edition; - creation of cleaned analytical datasets. | K56: The dashboard includes the following indicators: - number of FIFA World Cup editions; - number of matches; - number of participating national teams; - total goals; - average goals per match; - median goals per match; - number of draws; - number of penalty shootouts; - number of matches decided by a golden goal; - World Cup titles by team; | P56: - highest tournament stage reached; - wins, draws and defeats; - goals scored and conceded; - offensive performance score; - defensive performance score; - global performance score; - recent-form indicator; - expected goals; - estimated win, draw and loss probabilities; - model confidence indicator.
B77: TEAM PERFORMANCE SCORE | K77: VERSUS PROBABILITY MODEL
B78: The offensive, defensive and global scores are normalized indicators designed to compare national teams. The offensive score considers: average goals scored per match; consistency in goals scored; the volume of available match data. The defensive score considers: average goals conceded per match; consistency in goals conceded; clean-sheet performance; the volume of available match data. The global score combines the offensive and defensive dimensions. These scores are comparative indicators and must not be interpreted as official FIFA rankings. | K78: The VERSUS section compares two selected national teams. The model uses: average goals scored per match; average goals conceded per match; offensive and defensive adjustments; historical data reliability; recent form; expected-goal estimates; a Poisson distribution for score probabilities. The output includes: expected goals for each team; probability of a win for team A; probability of a draw; probability of a win for team B; most likely exact score; probability of the most likely score; confidence level.
B99: EXCEL SKILLS DEMONSTRATED | K99: LIMITATIONS
B100: This project demonstrates proficiency with: - Excel Tables; - structured references; - dynamic arrays; - data validation lists; - conditional formatting; - PivotTables; - PivotCharts; - dashboard design; - XLOOKUP; | G100: - SUMIFS; - COUNTIFS; - AVERAGEIFS; - FILTER; - UNIQUE; - SORT; - LET; - INDEX; - MATCH; - SUMPRODUCT; - Poisson probability functions. | K100: The analysis has several limitations: - team names and national entities have changed throughout World Cup history; - the number of available matches varies significantly between teams; - historical performances do not guarantee future results; - the expected-goals model does not include player availability, injuries, tactical systems or match location; - the Poisson model assumes independent scoring events;
B121: FUTURE IMPROVMENTS | K121: AUTHOR
B122: Future improvements may include: - migration of the cleaning process to Power Query; - SQL-based data preparation; - Power BI dashboard development; - Microsoft Fabric integration; - separation of historical and projected data; - home and away performance adjustments; - tournament-strength weighting; - opponent-strength adjustments; - model validation against historical matches; - confidence intervals and backtesting. | K122: Yann Lecompte Business Intelligence & Data Analytics Portfolio Current learning path: Excel → SQL → Power BI → Microsoft Fabric

Sheet DATA_DICTIONNAIRE
A2: Dataset : 2026_Team_ Summaries | G2: Dataset : Matches
A3: Field | B3: Data Type | C3: Nullable | D3: Description | E3: Example | G3: Field | H3: Data Type | I3: Nullable | J3: Description | K3: Example
A4: Country | B4: Text | C4: No | D4: National team represented in the FIFA World Cup dataset. | E4: France | G4: Year | H4: Integer | I4: No | J4: FIFA World Cup edition year. | K4: 1998
A5: 2026_Average_Age | B5: Decimal | C5: No | D5: Average age of the national team's squad selected for the 2026 FIFA World Cup. | E5: 27.4 | G5: Datetime | H5: DateTime | I5: No | J5: Date and time the match was played. | K5: 35988.875
A6: 2026_Unique_Clubs_Represented | B6: Integer | C6: No | D6: Number of different football clubs represented by players in the 2026 squad. | E6: 18 | G6: Stage | H6: Text | I6: No | J6: Tournament stage. | K6: Final
A7: Historical_Matches_Played | B7: Integer | C7: No | D7: Total number of FIFA World Cup matches played by the country since its first participation. | E7: 122 | G7: Stadium | H7: Text | I7: No | J7: Stadium where the match was played. | K7: Stade de France
A8: Historical_Goals_Scored | B8: Integer | C8: No | D8: Total number of goals scored by the country in FIFA World Cup history. | E8: 245 | G8: City | H8: Text | I8: No | J8: Host city of the match. | K8: Saint-Denis
G9: Home Team Name | H9: Text | I9: No | J9: Name of the home team. | K9: France
A10: Dataset : Penalty Shootouts | G10: Home Team Goals | H10: Integer | I10: No | J10: Number of goals scored by the home team. | K10: 3
A11: Field | B11: Data Type | C11: Nullable | D11: Description | E11: Example | G11: Away Team Goals | H11: Integer | I11: No | J11: Number of goals scored by the away team. | K11: 0
A12: Tournament_Year | B12: Integer | C12: No | D12: FIFA World Cup edition in which the penalty shootout occurred. | E12: 2022 | G12: Away Team Name | H12: Text | I12: No | J12: Name of the away team. | K12: Brazil
A13: Match_Stage | B13: Text | C13: No | D13: Tournament stage where the shootout took place. | E13: Quarter-finals | G13: Win conditions | H13: Text | I13: Yes | J13: Additional information about how the match was decided (extra time, penalties, etc.). | K13: France won after extra time
A14: Team_A | B14: Text | C14: No | D14: First team involved in the penalty shootout. | E14: Argentina
A15: Team_B | B15: Text | C15: No | D15: Second team involved in the penalty shootout. | E15: Netherlands | G15: Dataset : 2026 Squads
A16: Shooter_Team | B16: Text | C16: No | D16: Team of the player taking the penalty kick. | E16: Argentina | G16: Field | H16: Data Type | I16: Nullable | J16: Description | K16: Example
A17: Shooter_Name | B17: Text | C17: No | D17: Name of the player taking the penalty kick. | E17: Lionel Messi | G17: index | H17: Integer | I17: No | J17: Unique row identifier. | K17: 145
A18: Goalkeeper_Name | B18: Text | C18: No | D18: Name of the goalkeeper facing the penalty. | E18: Andries Noppert | G18: name | H18: Text | I18: No | J18: Player's full name. | K18: Kylian Mbappé
A19: Kick_Number | B19: Integer | C19: No | D19: Overall order of the penalty kick during the shootout. | E19: 5 | G19: age | H19: Integer | I19: No | J19: Player's age at the 2026 FIFA World Cup. | K19: 27
A20: Team_Kick_Number | B20: Integer | C20: No | D20: Order of the kick for the player's own team. | E20: 3 | G20: country | H20: Text | I20: No | J20: National team represented by the player. | K20: France
A21: Score_Before_Kick | B21: Text | C21: No | D21: Penalty shootout score before the kick was taken. | E21: 3–2 | G21: position | H21: Text | I21: No | J21: Playing position. | K21: Forward
A22: Is_Must_Score | B22: Boolean | C22: No | D22: Indicates whether the player had to score to keep the team alive. | E22: TRUE | G22: club | H22: Text | I22: No | J22: Professional club at the time of the tournament. | K22: Real Madrid
A23: Is_Winning_Kick | B23: Boolean | C23: No | D23: Indicates whether the kick secured the victory. | E23: FALSE | G23: jersey_number | H23: Integer | I23: No | J23: Shirt number worn during the tournament. | K23: 10
A24: Shoot_Outcome | B24: Text | C24: No | D24: Result of the penalty kick. | E24: Goal / Miss / Saved

Sheet KPI_DICTIONNAIRE
B2: KPI | C2: Catégorie | D2: Définition | E2: Source | F2: Format | G2: Interprétation
B3: Nombre d’éditions | C3: Vue d’ensemble | D3: Nombre d’années distinctes présentes dans les rencontres | E3: DATA_CLEANED!AF | F3: Entier | G3: Nombre d’éditions couvertes par le dataset
B4: Nombre de matchs | C4: Vue d’ensemble | D4: Nombre total de rencontres analysées | E4: DATA_CLEANED!AF:AO | F4: Entier | G4: Volume total de rencontres
B5: Nombre d’équipes | C5: Vue d’ensemble | D5: Nombre d’équipes distinctes ayant participé à au moins un match | E5: DATA_CLEANED!AK et AN | F5: Entier | G5: Couverture géographique du dataset
B6: Nombre total de buts | C6: Vue d’ensemble | D6: Somme des buts à domicile et à l’extérieur, hors tirs au but | E6: DATA_CLEANED!AL:AM | F6: Entier | G6: Production offensive totale
B7: Moyenne de buts par match | C7: Vue d’ensemble | D7: Total des buts divisé par le nombre de matchs | E7: DATA_CLEANED!AL:AM | F7: Décimal | G7: Intensité offensive moyenne
B8: Médiane de buts par match | C8: Vue d’ensemble | D8: Médiane du total de buts inscrits lors de chaque rencontre | E8: DATA_CLEANED!AL:AM | F8: Décimal | G8: Match typique, moins sensible aux scores extrêmes
B9: Nombre de matchs nuls | C9: Résultats | D9: Matchs terminés à égalité sans vainqueur après la procédure retenue | E9: Scores et conditions de victoire | F9: Entier | G9: Fréquence des matchs nuls
B10: Séances de tirs au but | C10: Résultats | D10: Nombre de rencontres décidées aux tirs au but | E10: Conditions de victoire et dataset des tirs au but | F10: Entier | G10: Fréquence des décisions aux tirs au but
B11: Matchs décidés par but en or | C11: Résultats | D11: Nombre de rencontres décidées selon la règle du but en or | E11: Conditions de victoire | F11: Entier | G11: Utilisation historique du but en or
B12: Participations | C12: Équipe | D12: Nombre d’éditions lors desquelles l’équipe a joué au moins un match | E12: CALCULES!B:X | F12: Entier | G12: Régularité de présence dans la compétition
B13: Matchs disputés | C13: Équipe | D13: Nombre total de matchs joués par l’équipe | E13: CALCULES!AA | F13: Entier | G13: Volume historique disponible
... B37: Indice de confiance | C37: Prédiction | D37: Niveau de fiabilité fondé sur le volume de matchs disponible pour les deux équipes | E37: Modèle VERSUS | F37: Faible, moyenne ou élevée | G37: Indique la robustesse relative de l’estimation

Sheet DATA_BRUT
A1: Dataset : 2026_Team_ Summaries | G1: Dataset : Penalty Shootouts (1982-2026) | U1: Dataset : 2026 Squads | AC1: Dataset : Matches (1930-2026)
A2: Country | B2: 2026_Average_Age | C2: 2026_Unique_Clubs_Represented | D2: Historical_Matches_Played | E2: Historical_Goals_Scored | G2: Tournament_Year | H2: Match_Stage | I2: Team_A | J2: Team_B | K2: Shooter_Team | L2: Shooter_Name | M2: Goalkeeper_Name | N2: Kick_Number | O2: Team_Kick_Number | P2: Score_Before_Kick | Q2: Is_Must_Score | R2: Is_Winning_Kick | S2: Shoot_Outcome | U2: index | V2: name | W2: age | X2: country | Y2: position | Z2: club | AA2: jersey_number | AC2: Year | AD2: Datetime | AE2: Stage | AF2: Stadium | AG2: City | AH2: Home Team Name | AI2: Home Team Goals | AJ2: Away Team Goals | AK2: Away Team Name | AL2: Win conditions
A3: Brazil | B3: 28.8 | C3: 20 | D3: 123 | E3: 251 | G3: 1982 | H3: Semi-finals | I3: West Germany | J3: France | K3: France | L3: Alain Giresse | M3: Harald Schumacher | N3: 1 | O3: 1 | P3: '0-0 | Q3: No | R3: No | S3: Goal | U3: 1 | V3: Matěj Kovář | W3: 26 | X3: Czech Republic | Y3: GK | Z3: PSV Eindhoven | AA3: 1 | AC3: 1930.0 | AD3: 13 Jul 1930 - 15:00 | AE3: Group 1 | AF3: Pocitos | AG3: Montevideo | AH3: France | AI3: 4.0 | AJ3: 1.0 | AK3: Mexico
A4: Argentina | B4: 28.7 | C4: 19 | D4: 98 | E4: 168 | G4: 1982 | H4: Semi-finals | I4: West Germany | J4: France | K4: West Germany | L4: Manfred Kaltz | M4: Jean-Luc Ettori | N4: 2 | O4: 1 | P4: '0-1 | Q4: No | R4: No | S4: Goal | U4: 2 | V4: Jindřich Staněk | W4: 30 | X4: Czech Republic | Y4: GK | Z4: Slavia Prague | AA4: 16 | AC4: 1930.0 | AD4: 13 Jul 1930 - 15:00 | AE4: Group 4 | AF4: Parque Central | AG4: Montevideo | AH4: USA | AI4: 3.0 | AJ4: 0.0 | AK4: Belgium
A5: France | B5: 26.6 | C5: 18 | D5: 82 | E5: 155 | G5: 1982 | H5: Semi-finals | I5: West Germany | J5: France | K5: France | L5: Manuel Amoros | M5: Harald Schumacher | N5: 3 | O5: 2 | P5: '1-1 | Q5: No | R5: No | S5: Goal | U5: 3 | V5: Lukáš Horníček | W5: 23 | X5: Czech Republic | Y5: GK | Z5: Braga | AA5: 23 | AC5: 1930.0 | AD5: 14 Jul 1930 - 12:45 | AE5: Group 2 | AF5: Parque Central | AG5: Montevideo | AH5: Yugoslavia | AI5: 2.0 | AJ5: 1.0 | AK5: Brazil
A6: England | B6: 26.7 | C6: 16 | D6: 81 | E6: 124 | G6: 1982 | H6: Semi-finals | I6: West Germany | J6: France | K6: West Germany | L6: Paul Breitner | M6: Jean-Luc Ettori | N6: 4 | O6: 2 | P6: '1-2 | Q6: No | R6: No | S6: Goal | U6: 4 | V6: David Zima | W6: 25 | X6: Czech Republic | Y6: CB | Z6: Slavia Prague | AA6: 2 | AC6: 1930.0 | AD6: 14 Jul 1930 - 14:50 | AE6: Group 3 | AF6: Pocitos | AG6: Montevideo | AH6: Romania | AI6: 3.0 | AJ6: 1.0 | AK6: Peru
A7: Germany | B7: 27.6 | C7: 13 | D7: 58 | E7: 123 | G7: 1982 | H7: Semi-finals | I7: West Germany | J7: France | K7: France | L7: Dominique Rocheteau | M7: Harald Schumacher | N7: 5 | O7: 3 | P7: '2-2 | Q7: No | R7: No | S7: Goal | U7: 5 | V7: Tomáš Holeš | W7: 33 | X7: Czech Republic | Y7: CB | Z7: Slavia Prague | AA7: 3 | AC7: 1930.0 | AD7: 15 Jul 1930 - 16:00 | AE7: Group 1 | AF7: Parque Central | AG7: Montevideo | AH7: Argentina | AI7: 1.0 | AJ7: 0.0 | AK7: France
A8: Spain | B8: 26.2 | C8: 13 | D8: 75 | E8: 122 | G8: 1982 | H8: Semi-finals | I8: West Germany | J8: France | K8: West Germany | L8: Uli Stielike | M8: Jean-Luc Ettori | N8: 6 | O8: 3 | P8: '2-3 | Q8: No | R8: No | S8: Saved | U8: 6 | V8: Robin Hranáč | W8: 26 | X8: Czech Republic | Y8: CB | Z8: TSG Hoffenheim | AA8: 4 | AC8: 1930.0 | AD8: 16 Jul 1930 - 14:45 | AE8: Group 1 | AF8: Parque Central | AG8: Montevideo | AH8: Chile | AI8: 3.0 | AJ8: 0.0 | AK8: Mexico
A9: Netherlands | B9: 27.3 | C9: 19 | D9: 63 | E9: 112 | G9: 1982 | H9: Semi-finals | I9: West Germany | J9: France | K9: France | L9: Didier Six | M9: Harald Schumacher | N9: 7 | O9: 4 | P9: '2-3 | Q9: No | R9: No | S9: Saved | U9: 7 | V9: Štěpán Chaloupek | W9: 23 | X9: Czech Republic | Y9: CB | Z9: Slavia Prague | AA9: 6 | AC9: 1930.0 | AD9: 17 Jul 1930 - 12:45 | AE9: Group 2 | AF9: Parque Central | AG9: Montevideo | AH9: Yugoslavia | AI9: 4.0 | AJ9: 0.0 | AK9: Bolivia
A10: Uruguay | B10: 28.2 | C10: 22 | D10: 63 | E10: 92 | G10: 1982 | H10: Semi-finals | I10: West Germany | J10: France | K10: West Germany | L10: Pierre Littbarski | M10: Jean-Luc Ettori | N10: 8 | O10: 4 | P10: '2-3 | Q10: No | R10: No | S10: Goal | U10: 8 | V10: Ladislav Krejčí | W10: 27 | X10: Czech Republic | Y10: CB | Z10: Wolverhampton Wanderers | AA10: 7 | AC10: 1930.0 | AD10: 17 Jul 1930 - 14:45 | AE10: Group 4 | AF10: Parque Central | AG10: Montevideo | AH10: USA | AI10: 3.0 | AJ10: 0.0 | AK10: Paraguay
A11: Sweden | B11: 27.0 | C11: 26 | D11: 55 | E11: 87 | G11: 1982 | H11: Semi-finals | I11: West Germany | J11: France | K11: France | L11: Michel Platini | M11: Harald Schumacher | N11: 9 | O11: 5 | P11: '3-3 | Q11: No | R11: No | S11: Goal | U11: 9 | V11: David Jurásek | W11: 25 | X11: Czech Republic | Y11: LB | Z11: Slavia Prague | AA11: 14 | AC11: 1930.0 | AD11: 18 Jul 1930 - 14:30 | AE11: Group 3 | AF11: Estadio Centenario | AG11: Montevideo | AH11: Uruguay | AI11: 1.0 | AJ11: 0.0 | AK11: Peru
A12: Belgium | B12: 27.1 | C12: 18 | D12: 59 | E12: 85 | G12: 1982 | H12: Semi-finals | I12: West Germany | J12: France | K12: West Germany | L12: Karl-Heinz Rummenigge | M12: Jean-Luc Ettori | N12: 10 | O12: 5 | P12: '3-4 | Q12: Yes | R12: No | S12: Goal | U12: 10 | V12: Jaroslav Zelený | W12: 33 | X12: Czech Republic | Y12: LB | Z12: Sparta Prague | AA12: 20 | AC12: 1930.0 | AD12: 19 Jul 1930 - 12:50 | AE12: Group 1 | AF12: Estadio Centenario | AG12: Montevideo | AH12: Chile | AI12: 1.0 | AJ12: 0.0 | AK12: France
A13: Mexico | B13: 27.5 | C13: 21 | D13: 66 | E13: 73 | G13: 1982 | H13: Semi-finals | I13: West Germany | J13: France | K13: France | L13: Maxime Bossis | M13: Harald Schumacher | N13: 11 | O13: 6 | P13: '4-4 | Q13: No | R13: No | S13: Saved | U13: 11 | V13: Vladimír Coufal | W13: 33 | X13: Czech Republic | Y13: RB | Z13: TSG Hoffenheim | AA13: 5 | AC13: 1930.0 | AD13: 19 Jul 1930 - 15:00 | AE13: Group 1 | AF13: Estadio Centenario | AG13: Montevideo | AH13: Argentina | AI13: 6.0 | AJ13: 3.0 | AK13: Mexico
A14: Switzerland | B14: 27.8 | C14: 24 | D14: 48 | E14: 65 | G14: 1982 | H14: Semi-finals | I14: West Germany | J14: France | K14: West Germany | L14: Horst Hrubesch | M14: Jean-Luc Ettori | N14: 12 | O14: 6 | P14: '4-4 | Q14: No | R14: Yes | S14: Goal | U14: 12 | V14: David Douděra | W14: 28 | X14: Czech Republic | Y14: RB | Z14: Slavia Prague | AA14: 21 | AC14: 1930.0 | AD14: 20 Jul 1930 - 13:00 | AE14: Group 2 | AF14: Estadio Centenario | AG14: Montevideo | AH14: Brazil | AI14: 4.0 | AJ14: 0.0 | AK14: Bolivia
... A20: Japan | B20: 26.9 | C20: 23 | D20: 29 | E20: 33 | G20: 1986 | H20: Quarter-finals | I20: Belgium | J20: Spain | K20: Spain | L20: Chendo | M20: Jean-Marie Pfaff | N20: 6 | O20: 3 | P20: '1-3 | Q20: No | R20: No | S20: Goal | U20: 18 | V20: Alexandr Sojka | W20: 23 | X20: Czech Republic | Y20: CM | Z20: Viktoria Plzeň | AA20: 24 | AC20: 1930.0 | AD20: 30 Jul 1930 - 14:15 | AE20: Final | AF20: Estadio Centenario | AG20: Montevideo | AH20: Uruguay | AI20: 4.0 | AJ20: 2.0 | AK20: Argentina
A21: Morocco | B21: 26.1 | C21: 24 | D21: 29 | E21: 30 | G21: 1986 | H21: Quarter-finals | I21: Belgium | J21: Spain | K21: Belgium | L21: Stephane Demol | M21: Andoni Zubizarreta | N21: 7 | O21: 4 | P21: '2-3 | Q21: No | R21: No | S21: Goal | U21: 19 | V21: Pavel Šulc | W21: 25 | X21: Czech Republic | Y21: CAM | Z21: Lyon | AA21: 15 | AC21: 1934.0 | AD21: 27 May 1934 - 16:30 | AE21: Preliminary round | AF21: Stadio Benito Mussolini | AG21: Turin | AH21: Austria | AI21: 3.0 | AJ21: 2.0 | AK21: France | AL21: Austria win after extra time
A22: Scotland | B22: 28.7 | C22: 22 | D22: 26 | E22: 26 | G22: 1986 | H22: Quarter-finals | I22: Belgium | J22: Spain | K22: Spain | L22: Butragueño | M22: Andoni Zubizarreta | N22: 8 | O22: 4 | P22: '2-4 | Q22: No | R22: No | S22: Goal | U22: 20 | V22: Hugo Sochůrek | W22: 18 | X22: Czech Republic | Y22: CAM | Z22: Sparta Prague | AA22: 25 | AC22: 1934.0 | AD22: 27 May 1934 - 16:30 | AE22: Preliminary round | AF22: Giorgio Ascarelli | AG22: Naples | AH22: Hungary | AI22: 4.0 | AJ22: 2.0 | AK22: Egypt
A23: Senegal | B23: 26.6 | C23: 22 | D23: 15 | E23: 24 | G23: 1986 | H23: Quarter-finals | I23: Belgium | J23: Spain | K23: Belgium | L23: Leo Van Der Elst | M23: Andoni Zubizarreta | N23: 9 | O23: 5 | P23: '3-4 | Q23: No | R23: Yes | S23: Goal | U23: 21 | V23: Adam Hložek | W23: 23 | X23: Czech Republic | Y23: LW | Z23: TSG Hoffenheim | AA23: 9 | AC23: 1934.0 | AD23: 27 May 1934 - 16:30 | AE23: Preliminary round | AF23: San Siro | AG23: Milan | AH23: Switzerland | AI23: 3.0 | AJ23: 2.0 | AK23: Netherlands
A24: Turkey | B24: 27.2 | C24: 16 | D24: 10 | E24: 20 | G24: 1986 | H24: Quarter-finals | I24: Brazil | J24: France | K24: Brazil | L24: Sócrates | M24: Joël Bats | N24: 1 | O24: 1 | P24: '0-0 | Q24: No | R24: No | S24: Saved | U24: 22 | V24: Denis Višinský | W24: 23 | X24: Czech Republic | Y24: RW | Z24: Viktoria Plzeň | AA24: 26 | AC24: 1934.0 | AD24: 27 May 1934 - 16:30 | AE24: Preliminary round | AF24: Littorale | AG24: Bologna | AH24: Sweden | AI24: 3.0 | AJ24: 2.0 | AK24: Argentina
A25: Australia | B25: 26.9 | C25: 22 | D25: 24 | E25: 20 | G25: 1986 | H25: Quarter-finals | I25: Brazil | J25: France | K25: France | L25: Yannick Stopyra | M25: Carlos | N25: 2 | O25: 1 | P25: '0-0 | Q25: No | R25: No | S25: Goal | U25: 23 | V25: Patrik Schick | W25: 30 | X25: Czech Republic | Y25: ST | Z25: Bayer Leverkusen | AA25: 10 | AC25: 1934.0 | AD25: 27 May 1934 - 16:30 | AE25: Preliminary round | AF25: Giovanni Berta | AG25: Florence | AH25: Germany | AI25: 5.0 | AJ25: 2.0 | AK25: Belgium
A26: Ghana | B26: 26.4 | C26: 23 | D26: 18 | E26: 20 | G26: 1986 | H26: Quarter-finals | I26: Brazil | J26: France | K26: Brazil | L26: Alemão | M26: Joël Bats | N26: 3 | O26: 2 | P26: '0-1 | Q26: No | R26: No | S26: Goal | U26: 24 | V26: Jan Kuchta | W26: 29 | X26: Czech Republic | Y26: ST | Z26: Sparta Prague | AA26: 11 | AC26: 1934.0 | AD26: 27 May 1934 - 16:30 | AE26: Preliminary round | AF26: Luigi Ferraris | AG26: Genoa | AH26: Spain | AI26: 3.0 | AJ26: 1.0 | AK26: Brazil
A27: Norway | B27: 26.3 | C27: 22 | D27: 13 | E27: 17 | G27: 1986 | H27: Quarter-finals | I27: Brazil | J27: France | K27: Brazil | L27: Alemão | M27: Joël Bats | N27: 3 | O27: 2 | P27: '1-0 | Q27: No | R27: No | S27: Goal | U27: 25 | V27: Mojmír Chytil | W27: 27 | X27: Czech Republic | Y27: ST | Z27: Slavia Prague | AA27: 13 | AC27: 1934.0 | AD27: 27 May 1934 - 16:30 | AE27: Preliminary round | AF27: Nazionale PNF | AG27: Rome | AH27: Italy | AI27: 7.0 | AJ27: 1.0 | AK27: USA
A28: Ecuador | B28: 25.6 | C28: 23 | D28: 17 | E28: 16 | G28: 1986 | H28: Quarter-finals | I28: Brazil | J28: France | K28: France | L28: Manuel Amoros | M28: Carlos | N28: 4 | O28: 2 | P28: '1-1 | Q28: No | R28: No | S28: Goal | U28: 26 | V28: Tomáš Chorý | W28: 31 | X28: Czech Republic | Y28: ST | Z28: Slavia Prague | AA28: 19 | AC28: 1934.0 | AD28: 27 May 1934 - 16:30 | AE28: Preliminary round | AF28: Littorio | AG28: Trieste | AH28: Czechoslovakia | AI28: 2.0 | AJ28: 1.0 | AK28: Romania
A29: Tunisia | B29: 26.2 | C29: 24 | D29: 21 | E29: 16 | G29: 1986 | H29: Quarter-finals | I29: Brazil | J29: France | K29: Brazil | L29: Zico | M29: Joël Bats | N29: 5 | O29: 3 | P29: '2-1 | Q29: No | R29: No | S29: Goal | U29: 27 | V29: Raúl Rangel | W29: 26 | X29: Mexico | Y29: GK | Z29: Guadalajara | AA29: 1 | AC29: 1934.0 | AD29: 31 May 1934 - 16:30 | AE29: Quarter-finals | AF29: Stadio Benito Mussolini | AG29: Turin | AH29: Czechoslovakia | AI29: 3.0 | AJ29: 2.0 | AK29: Switzerland
A30: Saudi Arabia | B30: 28.0 | C30: 9 | D30: 22 | E30: 15 | G30: 1986 | H30: Quarter-finals | I30: Brazil | J30: France | K30: France | L30: Bruno Bellone | M30: Carlos | N30: 6 | O30: 3 | P30: '2-2 | Q30: No | R30: No | S30: Goal | U30: 28 | V30: Carlos Acevedo | W30: 30 | X30: Mexico | Y30: GK | Z30: Santos Laguna | AA30: 12 | AC30: 1934.0 | AD30: 31 May 1934 - 16:30 | AE30: Quarter-finals | AF30: San Siro | AG30: Milan | AH30: Germany | AI30: 2.0 | AJ30: 1.0 | AK30: Sweden
A31: Algeria | B31: 26.5 | C31: 24 | D31: 16 | E31: 14 | G31: 1986 | H31: Quarter-finals | I31: Brazil | J31: France | K31: Brazil | L31: Branco | M31: Joël Bats | N31: 7 | O31: 4 | P31: '3-2 | Q31: No | R31: No | S31: Goal | U31: 29 | V31: Guillermo Ochoa | W31: 40 | X31: Mexico | Y31: GK | Z31: AEL Limassol | AA31: 13 | AC31: 1934.0 | AD31: 31 May 1934 - 16:30 | AE31: Quarter-finals | AF31: Giovanni Berta | AG31: Florence | AH31: Italy | AI31: 1.0 | AJ31: 1.0 | AK31: Spain
A32: Iran | B32: 29.8 | C32: 14 | D32: 15 | E32: 14 | G32: 1986 | H32: Quarter-finals | I32: Brazil | J32: France | K32: France | L32: Michel Platini | M32: Carlos | N32: 8 | O32: 4 | P32: '3-3 | Q32: No | R32: No | S32: Missed | U32: 30 | V32: César Montes | W32: 29 | X32: Mexico | Y32: CB | Z32: Lokomotiv Moscow | AA32: 3 | AC32: 1934.0 | AD32: 31 May 1934 - 16:30 | AE32: Quarter-finals | AF32: Littorale | AG32: Bologna | AH32: Austria | AI32: 2.0 | AJ32: 1.0 | AK32: Hungary
A33: Egypt | B33: 28.7 | C33: 14 | D33: 12 | E33: 13 | G33: 1986 | H33: Quarter-finals | I33: Brazil | J33: France | K33: Brazil | L33: Júlio César | M33: Joël Bats | N33: 9 | O33: 5 | P33: '3-3 | Q33: No | R33: No | S33: Missed | U33: 31 | V33: Johan Vásquez | W33: 27 | X33: Mexico | Y33: CB | Z33: Genoa | AA33: 5 | AC33: 1934.0 | AD33: 01 Jun 1934 - 16:30 | AE33: Quarter-finals | AF33: Giovanni Berta | AG33: Florence | AH33: Italy | AI33: 1.0 | AJ33: 0.0 | AK33: Spain
... A36: New Zealand | B36: 27.8 | C36: 19 | D36: 9 | E36: 8 | G36: 1986 | H36: Quarter-finals | I36: West Germany | J36: Mexico | K36: Mexico | L36: Manuel Negrete | M36: Harald Schumacher | N36: 2 | O36: 1 | P36: '1-0 | Q36: No | R36: No | S36: Goal | U36: 34 | V36: Jesús Gallardo | W36: 31 | X36: Mexico | Y36: LB | Z36: Toluca | AA36: 23 | AC36: 1934.0 | AD36: 07 Jun 1934 - 18:00 | AE36: Match for third place | AF36: Giorgio Ascarelli | AG36: Naples | AH36: Germany | AI36: 3.0 | AJ36: 2.0 | AK36: Austria
A37: Bosnia and Herzegovina | B37: 26.0 | C37: 24 | D37: 4 | E37: 5 | G37: 1986 | H37: Quarter-finals | I37: West Germany | J37: Mexico | K37: West Germany | L37: Andreas Brehme | M37: Pablo Larios | N37: 3 | O37: 2 | P37: '1-1 | Q37: No | R37: No | S37: Goal | U37: 35 | V37: Jorge Sánchez | W37: 28 | X37: Mexico | Y37: RB | Z37: PAOK | AA37: 2 | AC37: 1934.0 | AD37: 10 Jun 1934 - 17:30 | AE37: Final | AF37: Nazionale PNF | AG37: Rome | AH37: Italy | AI37: 2.0 | AJ37: 1.0 | AK37: Czechoslovakia | AL37: Italy win after extra time
A38: Côte d'Ivoire | B38: 25.3 | C38: 25 | D38: 3 | E38: 4 | G38: 1986 | H38: Quarter-finals | I38: West Germany | J38: Mexico | K38: Mexico | L38: Fernando Quirarte | M38: Harald Schumacher | N38: 4 | O38: 2 | P38: '1-2 | Q38: No | R38: No | S38: Saved | U38: 36 | V38: Edson Álvarez | W38: 28 | X38: Mexico | Y38: CDM | Z38: Fenerbahçe | AA38: 4 | AC38: 1938.0 | AD38: 04 Jun 1938 - 17:00 | AE38: First round | AF38: Parc des Princes | AG38: Paris | AH38: Switzerland | AI38: 1.0 | AJ38: 1.0 | AK38: Germany
A39: Haiti | B39: 27.0 | C39: 25 | D39: 6 | E39: 4 | G39: 1986 | H39: Quarter-finals | I39: West Germany | J39: Mexico | K39: West Germany | L39: Lothar Matthäus | M39: Pablo Larios | N39: 5 | O39: 3 | P39: '1-2 | Q39: No | R39: No | S39: Goal | U39: 37 | V39: Érik Lira | W39: 26 | X39: Mexico | Y39: CDM | Z39: Cruz Azul | AA39: 6 | AC39: 1938.0 | AD39: 05 Jun 1938 - 17:00 | AE39: First round | AF39: Velodrome Municipale | AG39: Reims | AH39: Hungary | AI39: 6.0 | AJ39: 0.0 | AK39: Dutch East Indies
A40: USA | B40: 26.4 | C40: 24 | D40: 5 | E40: 4 | G40: 1986 | H40: Quarter-finals | I40: West Germany | J40: Mexico | K40: Mexico | L40: Raúl Servín | M40: Harald Schumacher | N40: 6 | O40: 3 | P40: '1-3 | Q40: No | R40: No | S40: Saved | U40: 38 | V40: Obed Vargas | W40: 20 | X40: Mexico | Y40: CDM | Z40: Atlético Madrid | AA40: 18 | AC40: 1938.0 | AD40: 05 Jun 1938 - 17:00 | AE40: First round | AF40: Stade Olympique | AG40: Colombes | AH40: France | AI40: 3.0 | AJ40: 1.0 | AK40: Belgium
A41: Qatar | B41: 28.9 | C41: 8 | D41: 6 | E41: 3 | G41: 1986 | H41: Quarter-finals | I41: West Germany | J41: Mexico | K41: West Germany | L41: Pierre Littbarski | M41: Pablo Larios | N41: 7 | O41: 4 | P41: '1-3 | Q41: No | R41: Yes | S41: Goal | U41: 39 | V41: Luis Romo | W41: 31 | X41: Mexico | Y41: CM | Z41: Guadalajara | AA41: 7 | AC41: 1938.0 | AD41: 05 Jun 1938 - 17:00 | AE41: First round | AF41: Stade Municipal | AG41: Toulouse | AH41: Cuba | AI41: 3.0 | AJ41: 3.0 | AK41: Romania
A42: Czech Republic | B42: 27.2 | C42: 11 | D42: 3 | E42: 2 | G42: 1990 | H42: Round of 16 | I42: Republic of Ireland | J42: Romania | K42: Republic of Ireland | L42: Kevin Sheedy | M42: Silviu Lung | N42: 1 | O42: 1 | P42: '0-0 | Q42: No | R42: No | S42: Goal | U42: 40 | V42: Álvaro Fidalgo | W42: 29 | X42: Mexico | Y42: CM | Z42: Real Betis | AA42: 8 | AC42: 1938.0 | AD42: 05 Jun 1938 - 17:00 | AE42: First round | AF42: Stade V�lodrome | AG42: Marseilles | AH42: Italy | AI42: 2.0 | AJ42: 1.0 | AK42: Norway | AL42: Italy win after extra time
A43: Panama | B43: 30.0 | C43: 23 | D43: 6 | E43: 2 | G43: 1990 | H43: Round of 16 | I43: Republic of Ireland | J43: Romania | K43: Romania | L43: Gheorghe Hagi | M43: Pat Bonner | N43: 2 | O43: 1 | P43: '1-0 | Q43: No | R43: No | S43: Goal | U43: 41 | V43: Luis Chávez | W43: 30 | X43: Mexico | Y43: CM | Z43: Dynamo Moscow | AA43: 24 | AC43: 1938.0 | AD43: 05 Jun 1938 - 17:30 | AE43: First round | AF43: Stade de la Meinau | AG43: Strasbourg | AH43: Brazil | AI43: 6.0 | AJ43: 5.0 | AK43: Poland | AL43: Brazil win after extra time
A44: Iraq | B44: 26.4 | C44: 20 | D44: 5 | E44: 2 | G44: 1990 | H44: Round of 16 | I44: Republic of Ireland | J44: Romania | K44: Republic of Ireland | L44: Ray Houghton | M44: Silviu Lung | N44: 3 | O44: 2 | P44: '1-1 | Q44: No | R44: No | S44: Goal | U44: 42 | V44: Orbelín Pineda | W44: 30 | X44: Mexico | Y44: CAM | Z44: AEK Athens | AA44: 17 | AC44: 1938.0 | AD44: 05 Jun 1938 - 18:30 | AE44: First round | AF44: Cavee Verte | AG44: Le Havre | AH44: Czechoslovakia | AI44: 3.0 | AJ44: 0.0 | AK44: Netherlands | AL44: Czechoslovakia win after extra time
A45: Uzbekistan | B45: 27.7 | C45: 16 | D45: 1 | E45: 1 | G45: 1990 | H45: Round of 16 | I45: Republic of Ireland | J45: Romania | K45: Romania | L45: Dănuț Lupu | M45: Pat Bonner | N45: 4 | O45: 2 | P45: '1-2 | Q45: No | R45: No | S45: Goal | U45: 43 | V45: Gilberto Mora | W45: 17 | X45: Mexico | Y45: CAM | Z45: Tijuana | AA45: 19 | AC45: 1938.0 | AD45: 09 Jun 1938 - 18:00 | AE45: First round | AF45: Stade Municipal | AG45: Toulouse | AH45: Cuba | AI45: 2.0 | AJ45: 1.0 | AK45: Romania
A46: Curaçao | B46: 27.5 | C46: 22 | D46: 3 | E46: 1 | G46: 1990 | H46: Round of 16 | I46: Republic of Ireland | J46: Romania | K46: Republic of Ireland | L46: Andy Townsend | M46: Silviu Lung | N46: 5 | O46: 3 | P46: '2-2 | Q46: No | R46: No | S46: Goal | U46: 44 | V46: Brian Gutiérrez | W46: 22 | X46: Mexico | Y46: CAM | Z46: Guadalajara | AA46: 26 | AC46: 1938.0 | AD46: 09 Jun 1938 - 18:00 | AE46: First round | AF46: Parc des Princes | AG46: Paris | AH46: Switzerland | AI46: 4.0 | AJ46: 2.0 | AK46: Germany
A47: Jordan | B47: 28.1 | C47: 14 | D47: 1 | E47: 1 | G47: 1990 | H47: Round of 16 | I47: Republic of Ireland | J47: Romania | K47: Romania | L47: Ioan Sabău | M47: Pat Bonner | N47: 6 | O47: 3 | P47: '2-3 | Q47: No | R47: No | S47: Goal | U47: 45 | V47: Alexis Vega | W47: 28 | X47: Mexico | Y47: LW | Z47: Toluca | AA47: 10 | AC47: 1938.0 | AD47: 12 Jun 1938 - 17:00 | AE47: Quarter-finals | AF47: Stade du Parc Lescure | AG47: Bordeaux | AH47: Brazil | AI47: 1.0 | AJ47: 1.0 | AK47: Czechoslovakia
...

Sheet DATA_QUALITE
A1: Raccourcis : | B1: HAUT DE PAGE | C1: DOUBLONS | D1: NOM DE PAYS | E1: CARACTERE SPECIAL | F1: DONNEES NUMERIQUES | G1: ETAPES DU CHAMPIONNAT
A2: HAUT DE PAGE
A3: DOUBLONS | C3: DOUBLONS | R3: NOM DE PAYS | NORMALISATION | Z3: CARACTERE SPECIAL | CORRECTION | AE3: DONNEES NUMERIQUES | NORMALISATION | AS3: ETAPES DU CHAMPIONNAT | NORMALISATION | AY3: ETAPES DU CHAMPIONNAT | VERIFICATION | BE3: VERIFICATION DU SCORE | BK3: NOMBRE DE MATCHS | VERIFICATION
A4: NOM DE PAYS | NORMALISATION | C4: Dataset : 2026_Team_ Summaries | D4: =IF(COUNTIF(H32:H79,"DOUBLON")=0,"PAS DE DOUBLONS","DOUBLONS = "&COUNTIF(H32:H79,"DUPLICATE")) -> PAS DE DOUBLONS | R4: Dataset : 2026_Team_ Summaries | S4: =IF(COUNTIF(T$13:T$60,"ERREUR")>0,"ERREURS DETECTEES = "&COUNTIF(T$13:T$60,"ERREUR")&" || ACTIONS APPORTEES : *AUCUNE = "&COUNTIF(U$13:U$60,"AUCUNE")&" *RENOMMER = "&COUNTIF(U$13:U$60,"RENOMMER"),"PAS D'ACTIONS ENTREPRISES") -> ERREURS DETECTEES = 6 || ACTIONS APPORTEES : *AUCUNE = 2 *RENOMMER = 4 | Z4: Dataset : 2026_Team_ Summaries | AA4: =IF(AB11="Aucuns caractères spéciaux détectés","PAS DE CORRECTIONS","ERREURS A CORRIGER") -> PAS DE CORRECTIONS | AE4: Dataset : 2026_Team_ Summaries | AF4: ="Colonne à convertir (texte > numérique) : "&COUNTIF(AE14:AI14,"OUI") -> Colonne à convertir (texte > numérique) : 1 | AS4: Dataset : 2026_Team_ Summaries | AT4: Pas d'étapes | AY4: Dataset : 2026_Team_ Summaries | AZ4: Pas d'étapes | BE4: Dataset : 2026_Team_ Summaries | BF4: Pas de score | BK4: Dataset : 2026_Team_ Summaries | BL4: Ne contient pas de match
A5: CARACTERE SPECIAL | CORRECTION | C5: Dataset : Penalty Shootouts (1982-2026) | D5: =IF(COUNTIF(P83:P434,"DOUBLON")=0,"PAS DE DOUBLONS","DOUBLONS = "&COUNTIF(P83:P434,"DUPLICATE")) -> PAS DE DOUBLONS | R5: Dataset : Penalty Shootouts (1982-2026) | S5: =IF(COUNTIF(T$63:T$1118,"ERREUR")>0,"ERREURS DETECTEES = "&COUNTIF(T$63:T$1118,"ERREUR")&" || ACTIONS APPORTEES : *AUCUNE = "&COUNTIF(U$63:U$1118,"AUCUNE")&" *RENOMMER = "&COUNTIF(U$63:U$1118,"RENOMMER"),"PAS D'ACTIONS ENTREPRISES") -> ERREURS DETECTEES = 141 || ACTIONS APPORTEES : *AUCUNE = 71 *RENOMMER = 70 | Z5: Dataset : Penalty Shootouts (1982-2026) | AA5: =IF(AND(AB12="Aucuns caractères spéciaux détectés",AB13="Aucuns caractères spéciaux détectés"),"PAS DE CORRECTIONS","ERREURS A CORRIGER") -> PAS DE CORRECTIONS | AE5: Dataset : Penalty Shootouts (1982-2026) | AF5: ="Colonne à convertir (texte > numérique) : "&COUNTIF(AE68:AQ68,"OUI") -> Colonne à convertir (texte > numérique) : 0 | AS5: Dataset : Penalty Shootouts (1982-2026) | AT5: OK | AY5: Dataset : Penalty Shootouts (1982-2026) | AZ5: Pas d'étapes | BE5: Dataset : Penalty Shootouts (1982-2026) | BF5: Pas de score | BK5: Dataset : Penalty Shootouts (1982-2026) | BL5: Ne contient pas de match
A6: DONNEES NUMERIQUES | NORMALISATION | C6: Dataset : 2026 Squads | D6: =IF(COUNTIF(J438:J1685,"DOUBLON")=0,"PAS DE DOUBLONS","DOUBLONS = "&COUNTIF(J438:J1685,"DUPLICATE")) -> PAS DE DOUBLONS | R6: Dataset : 2026 Squads | S6: =IF(COUNTIF(T$1121:T$2368,"ERREUR")>0,"ERREURS DETECTEES = "&COUNTIF(T$1121:T$2368,"ERREUR")&" || ACTIONS APPORTEES : *AUCUNE = "&COUNTIF(U$1121:U$2368,"AUCUNE")&" *RENOMMER = "&COUNTIF(U$1121:U$2368,"RENOMMER"),"PAS D'ACTIONS ENTREPRISES") -> ERREURS DETECTEES = 156 || ACTIONS APPORTEES : *AUCUNE = 52 *RENOMMER = 104 | Z6: Dataset : 2026 Squads | AA6: =IF(AND(AB14="Aucuns caractères spéciaux détectés",AB15="Aucuns caractères spéciaux détectés"),"PAS DE CORRECTIONS","ERREURS A CORRIGER") -> PAS DE CORRECTIONS | AE6: Dataset : 2026 Squads | AF6: ="Colonne à convertir (texte > numérique) : "&COUNTIF(AE75:AK75,"OUI") -> Colonne à convertir (texte > numérique) : 0 | AS6: Dataset : 2026 Squads | AT6: Pas d'étapes | AY6: Dataset : 2026 Squads | AZ6: Pas d'étapes | BE6: Dataset : 2026 Squads | BF6: Pas de score | BK6: Dataset : 2026 Squads | BL6: Ne contient aucun match
A7: ETAPES DU CHAMPIONNAT | NORMALISATION | C7: Dataset : Matches (1930-2026) | D7: =IF(COUNTIF(M1689:M2762,"DOUBLON")=0,"PAS DE DOUBLONS","DOUBLONS = "&COUNTIF(M1689:M2762,"DOUBLON")) -> DOUBLONS = 16 | R7: Dataset : Matches (1930-2026) | S7: =IF(COUNTIF(T2371:T4486,"ERREUR")>0,"ERREURS DETECTEES = "&COUNTIF(T2371:T4486,"ERREUR")&" || ACTIONS APPORTEES : *AUCUNE = "&COUNTIF(U2371:U4486,"AUCUNE")&" *RENOMMER = "&COUNTIF(U2371:U4486,"RENOMMER"),"PAS D'ACTIONS ENTREPRISES") -> ERREURS DETECTEES = 428 || ACTIONS APPORTEES : *AUCUNE = 230 *RENOMMER = 198 | Z7: Dataset : Matches (1930-2026) | AA7: =IF(AB16="Aucuns caractères spéciaux détectés","PAS DE CORRECTIONS","ERREURS A CORRIGER") -> ERREURS A CORRIGER | AE7: Dataset : Matches (1930-2026) | AF7: ="Colonne à convertir (texte > numérique) : "&COUNTIF(AE82:AN82,"OUI") -> Colonne à convertir (texte > numérique) : 3 | AS7: Dataset : Matches (1930-2026) | AT7: OK | AY7: Dataset : Matches (1930-2026) | AZ7: =IF(COUNTIF(BC12:BC71,"OK")<COUNTA(BC12:BC71),"ERREUR","OK") -> OK | BE7: Dataset : Matches (1930-2026) | BF7: =IF(COUNTIF(BF12:BF1069,"OK")<COUNTA(BF12:BF1069),"ERREUR","OK") -> OK | BK7: Dataset : Matches (1930-2026) | BL7: =IF(COUNTIF(BN12:BN34,"OK")<COUNTA(BN12:BN34),"ERREUR","OK") -> ERREUR
A8: ETAPES DU CHAMPIONNAT | VERIFICATION | R8: Colonne Win Conditions | S8: =IF(COUNTA(T4489:T5546)-COUNTIF(T4489:T5546,"-")>0,"ERREURS DETECTEES = "&COUNTA(T4489:T5546)-COUNTIF(T4489:T5546,"-")&" || ACTIONS APPORTEES : *AUCUNE = "&COUNTIF(U4489:U5546,"AUCUNE")&" *RENOMMER = "&COUNTIF(U4489:U5546,"RENOMMER"),"PAS D'ACTIONS ENTREPRISES") -> ERREURS DETECTEES = 69 || ACTIONS APPORTEES : *AUCUNE = 66 *RENOMMER = 3
A9: VERIFICATION DU SCORE
A10: NOMBRE DE MATCHS | VERIFICATION | B10: Vérification des doublons : | AB10: Caractère spécial trouvé | AE10: Dataset : 2026_Team_ Summaries | AY10: Dataset : Matches (1930-2026) | BE10: Dataset : Matches (1930-2026) | BK10: Dataset : Matches (1930-2026)
B11: ACTION | C11: Dataset : Matches (1930-2026) | R11: Tableau de correspondance | Z11: Dataset : 2026_Team_ Summaries | AA11: Country | AB11: {=_xlfn._xlws.FILTER(DATA_BRUT!A2:A50,ISNUMBER(SEARCH(_xlfn.UNICHAR(65533),DATA_BRUT!A2:A50)),"Aucuns caractères spéciaux détectés")} -> Aucuns caractères spéciaux détectés | AE11: ="Nombre de colonnes : "&COLUMNS(DATA_BRUT!A2:E2) -> Nombre de colonnes : 5 | AS11: Tableau de correspondance | AV11: Dataset : Penalty Shootouts (1982-2026) | AW11: Dataset : Matches (1930-2026) | AY11: ANNEE | AZ11: ETAPE | BA11: ATTENDU | BB11: ACTUEL | BC11: STATUS | BE11: Validité du score | BF11: TEAM_VALIDE | BG11: GAGNANT | BH11: CONDITIONS | BI11: GAGNANT_VALIDE | BK11: ANNEE | BL11: Nombre de matchs ATTENDU | BM11: Nombre de matchs ACTUEL | BN11: STATUS
B12: =UPPER("retiré") -> RETIRÉ | C12: {=_xlfn._xlws.FILTER(B1689:M2762,M1689:M2762="DOUBLON")} -> 2014.0 | D12: 28 Jun 2014 - 13:00 | E12: Round of 16 | F12: Estadio Mineirao | G12: Belo Horizonte | H12: Brazil | I12: 1.0 | J12: 1.0 | K12: Chile | L12: Brazil win on penalties (3 - 2) | M12: 2014.0|28 Jun 2014 - 13:00 |Round of 16|Estadio Mineirao|Belo Horizonte |Brazil|1.0|1.0|Chile|Brazil win on penalties (3 - 2) | N12: DOUBLON | R12: Liste des pays du monde | S12: Dataset : 2026_Team_ Summaries | T12: STATUS | U12: ACTION | V12: CORRECTION APPORTEE | W12: Liste des pays DATASET (corrigée) | X12: Liste des pays FIFA (unique) | Z12: Dataset : Penalty Shootouts (1982-2026) | AA12: Shooter_Name | AB12: {=_xlfn._xlws.FILTER(DATA_BRUT!G2:S354,ISNUMBER(SEARCH(_xlfn.UNICHAR(65533),DATA_BRUT!L2:L354)),"Aucuns caractères spéciaux détectés")} -> Aucuns caractères spéciaux détectés | AD12: Colonne | AE12: {=DATA_BRUT!A2:E2} -> Country | AF12: 2026_Average_Age | AG12: 2026_Unique_Clubs_Represented | AH12: Historical_Matches_Played | AI12: Historical_Goals_Scored | AS12: {=_xlfn._xlws.SORT(_xlfn.UNIQUE(_xlfn.VSTACK(DATA_BRUT!H3:H354,DATA_BRUT!AE3:AE1076)))} -> Final | AT12: FINAL | AU12: 1 | AV12: {=_xlfn.XLOOKUP(DATA_BRUT!H3:H354,_xlfn.ANCHORARRAY(DATA_QUALITE!AS12),DATA_QUALITE!AT12:AT38)} -> SEMI_FINALS | AW12: {=_xlfn._xlws.FILTER(_xlfn.XLOOKUP(DATA_BRUT!AE3:AE1076,_xlfn.ANCHORARRAY(DATA_QUALITE!AS12),DATA_QUALITE!AT12:AT38),M1689:M2762="OK")} -> GROUP_STAGE | AY12: {=INDEX(_xlfn.UNIQUE(DATA_CLEANED!AF3:'DATA_CLEANED'!AF1060),INT((ROWS(AY$12:AY12)-1)/3)+1)} -> 1930 | AZ12: QUARTER_FINALS | BA12: 0 | BB12: =COUNTIFS(DATA_CLEANED!AH$3:AH$1060,AZ12,DATA_CLEANED!AF$3:AF$1060,AY12) -> 0 | BC12: =IF(BA12>BB12,"Donnée manquante",IF(BA12<BB12,"A VERIFIER","OK")) -> OK | BE12: =IF(OR(DATA_CLEANED!AL3="",DATA_CLEANED!AM3=""),"MANQUANT",IF(OR(NOT(ISNUMBER(DATA_CLEANED!AL3)),NOT(ISNUMBER(DATA_CLEANED!AM3))),"ENTREE INVALIDE",IF(OR(DATA_CLEANED!AL3<0,DATA_CLEANED!AM3<0),"SCORE NEGATIF","OK"))) -> OK | BF12: =IF(DATA_CLEANED!AK3<>DATA_CLEANED!AN3,"OK","ERREUR") -> OK | BG12: =IF(DATA_CLEANED!AL3>DATA_CLEANED!AM3,DATA_CLEANED!AK3,IF(AND(DATA_QUALITE!W4489="-",DATA_CLEANED!AM3=DATA_CLEANED!AL3),"MATCH NUL",IF(AND(DATA_QUALITE!V4489="-",DATA_QUALITE!U4489="AUCUNE"),DATA_QUALITE!T4489,IF(DATA_QUALITE!V4489<>"-",DATA_QUALITE!V4489,DATA_CLEANED!AN3)))) -> France | BH12: =IF(AND(BG12="MATCH NUL",DATA_CLEANED!AO3="-"),"MATCH_NUL",IF(ISNUMBER(SEARCH("win on penalties",W4489)),"WIN_BY_PENALTY",IF(ISNUMBER(SEARCH("win after extra time",W4489)),"WIN_BY_EXTRA_TIME",IF(ISNUMBER(SEARCH("Golden Goal",W4489)),"WIN_BY_GOLDEN_GOAL","WIN_BY_SCORE")))) -> WIN_BY_SCORE | BI12: =IF(OR(BG12=DATA_CLEANED!AK3,BG12=DATA_CLEANED!AN3,BG12="MATCH NUL"),"OK","ERREUR") -> OK | BK12: {=_xlfn.UNIQUE(_xlfn.ANCHORARRAY(DATA_CLEANED!AF3))} -> 1930 | BL12: 18 | BM12: {=RESUME!F16:F38} -> 18 | BN12: =IF(BL12=BM12,"OK","MATCH_MANQUANTS") -> OK
B13: =UPPER("retiré") -> RETIRÉ | C13: 2014.0 | D13: 28 Jun 2014 - 17:00 | E13: Round of 16 | F13: Estadio do Maracana | G13: Rio De Janeiro | H13: Colombia | I13: 2.0 | J13: 0.0 | K13: Uruguay | M13: 2014.0|28 Jun 2014 - 17:00 |Round of 16|Estadio do Maracana|Rio De Janeiro |Colombia|2.0|0.0|Uruguay| | N13: DOUBLON | R13: Afghanistan | S13: {=DATA_BRUT!A3:A50} -> Brazil | T13: =IF(COUNTIF(R$13:R$250,S13)=1,"OK","ERREUR") -> OK | U13: =IF(OR(S13="Scotland",S13="England",S13="Wales",S13="Yugoslavia",S13="Czechoslovakia",S13="Northern Ireland",S13="Soviet Union",S13="Zaire",S13="Dutch East Indies"),"AUCUNE",IF(OR(S13="Cape Verde",S13="USA",S13="DR Congo",S13="Republic of Korea",S13="Germany FR",S13="Germany DR",S13="Czechia",S13="Ivory Coast",S13="Korea DPR",S13="China PR",S13="IR Iran",S13="Türkiye",S13="Congo DR",S13="German DR",ISNUMBER(SEARCH("rn"">United Arab Emirates",S13)),ISNUMBER(SEARCH("rn"">Republic of Ireland",S13)),ISNUMBER(SEARCH("rn"">Bosnia and Herzegovina",S13)),ISNUMBER(SEARCH("rn"">Trinidad and Tobago",S13)),ISNUMBER(SEARCH("rn"">Serbia and Montenegro",S13)),ISNUMBER(SEARCH(_xlfn.UNICHAR(65533),S13))),"RENOMMER","-")) -> - | V13: {=_xlfn.IFS( ISNUMBER(SEARCH("USA",S13)),"United States", ISNUMBER(SEARCH("Republic of Korea",S13)),"South Korea", ISNUMBER(SEARCH("Cape Verde",S13)),"Cabo Verde", ISNUMBER(SEARCH("Czechia",S13)),"Czech Republic", ISNUMBER(SEARCH("Türkiye",S13)),"Turkey", ISNUMBER(SEARCH("Ivory Coast",S13)),"Côte d'Ivoire", ISNUMBER(SEARCH("Korea Republic",S13)),"South Korea", ISNUMBER(SEARCH("Germany FR",S13)),"FR Germany", ISNUMBER(SEARCH("Germany DR",S13)),"DR Germany", ISNUMBER(SEARCH("Korea DPR",S13)),"North Korea", ISNUMBER(SEARCH("China PR",S13)),"China", ISNUMBER(SEARCH("IR Iran",S13)),"Iran", ISNUMBER(SEARCH("Congo DR",S13)),"Democratic Republic of the Congo", ISNUMBER(SEARCH("DR Congo",S13)),"Democratic Republic of the Congo", ISNUMBER(SEARCH("German DR",S13)),"DR Germany", ISNUMBER(SEARCH("rn"">United Arab Emirates",S13)),"United Arab Emirates", ISNUMBER(SEARCH("rn"">Republic of Ireland",S13)),"Ireland", ISNUMBER(SEARCH("rn"">Bosnia and Herzegovina",S13)),"Bosnia and Herzegovina", ISNUMBER(SEARCH("rn"">Trinidad and Tobago",S13)),"Trinidad and Tobago", ISNUMBER(SEARCH("rn"">Serbia and Montenegro",S13)),"Serbia and Montenegro", ISNUMBER(SEARCH(_xlfn.UNICHAR(65533),S13)),"Côte d'Ivoire", TRUE,"" )} | W13: =IF(V13="",S13,V13) -> Brazil | X13: {=_xlfn._xlws.SORT(_xlfn.UNIQUE(_xlfn.VSTACK(_xlfn.UNIQUE(W13:W60),_xlfn.UNIQUE(W63:W1118),_xlfn.UNIQUE(W1121:W2368),_xlfn.UNIQUE(W2371:W4486))),1,1)} -> Algeria | AA13: Goalkeeper_Name | AB13: {=_xlfn._xlws.FILTER(DATA_BRUT!G2:S354,ISNUMBER(SEARCH(_xlfn.UNICHAR(65533),DATA_BRUT!M2:M354)),"Aucuns caractères spéciaux détectés")} -> Aucuns caractères spéciaux détectés | AD13: Est numérique | AE13: {=ISNUMBER(DATA_BRUT!A3:E3)} -> FALSE | AF13: FALSE | AG13: TRUE | AH13: TRUE | AI13: TRUE | AS13: Finals | AT13: FINAL | AU13: 1 | AV13: SEMI_FINALS | AW13: GROUP_STAGE | AY13: {=INDEX(_xlfn.UNIQUE(DATA_CLEANED!AF4:'DATA_CLEANED'!AF1061),INT((ROWS(AY$12:AY13)-1)/3)+1)} -> 1930 | AZ13: SEMI_FINALS | BA13: 2 | BB13: =COUNTIFS(DATA_CLEANED!AH$3:AH$1060,AZ13,DATA_CLEANED!AF$3:AF$1060,AY13) -> 2 | BC13: =IF(BA13>BB13,"Donnée manquante",IF(BA13<BB13,"A VERIFIER","OK")) -> OK | BE13: =IF(OR(DATA_CLEANED!AL4="",DATA_CLEANED!AM4=""),"MANQUANT",IF(OR(NOT(ISNUMBER(DATA_CLEANED!AL4)),NOT(ISNUMBER(DATA_CLEANED!AM4))),"ENTREE INVALIDE",IF(OR(DATA_CLEANED!AL4<0,DATA_CLEANED!AM4<0),"SCORE NEGATIF","OK"))) -> OK | BF13: =IF(DATA_CLEANED!AK4<>DATA_CLEANED!AN4,"OK","ERREUR") -> OK | BG13: =IF(DATA_CLEANED!AL4>DATA_CLEANED!AM4,DATA_CLEANED!AK4,IF(AND(DATA_QUALITE!W4490="-",DATA_CLEANED!AM4=DATA_CLEANED!AL4),"MATCH NUL",IF(AND(DATA_QUALITE!V4490="-",DATA_QUALITE!U4490="AUCUNE"),DATA_QUALITE!T4490,IF(DATA_QUALITE!V4490<>"-",DATA_QUALITE!V4490,DATA_CLEANED!AN4)))) -> United States | BH13: =IF(AND(BG13="MATCH NUL",DATA_CLEANED!AO4="-"),"MATCH_NUL",IF(ISNUMBER(SEARCH("win on penalties",W4490)),"WIN_BY_PENALTY",IF(ISNUMBER(SEARCH("win after extra time",W4490)),"WIN_BY_EXTRA_TIME",IF(ISNUMBER(SEARCH("Golden Goal",W4490)),"WIN_BY_GOLDEN_GOAL","WIN_BY_SCORE")))) -> WIN_BY_SCORE | BI13: =IF(OR(BG13=DATA_CLEANED!AK4,BG13=DATA_CLEANED!AN4,BG13="MATCH NUL"),"OK","ERREUR") -> OK | BK13: 1934 | BL13: 17 | BM13: 17 | BN13: =IF(BL13=BM13,"OK","MATCH_MANQUANTS") -> OK
B14: =UPPER("retiré") -> RETIRÉ | C14: 2014.0 | D14: 29 Jun 2014 - 13:00 | E14: Round of 16 | F14: Estadio Castelao | G14: Fortaleza | H14: Netherlands | I14: 2.0 | J14: 1.0 | K14: Mexico | M14: 2014.0|29 Jun 2014 - 13:00 |Round of 16|Estadio Castelao|Fortaleza |Netherlands|2.0|1.0|Mexico| | N14: DOUBLON | R14: Albania | S14: Argentina | T14: =IF(COUNTIF(R$13:R$250,S14)=1,"OK","ERREUR") -> OK | U14: =IF(OR(S14="Scotland",S14="England",S14="Wales",S14="Yugoslavia",S14="Czechoslovakia",S14="Northern Ireland",S14="Soviet Union",S14="Zaire",S14="Dutch East Indies"),"AUCUNE",IF(OR(S14="Cape Verde",S14="USA",S14="DR Congo",S14="Republic of Korea",S14="Germany FR",S14="Germany DR",S14="Czechia",S14="Ivory Coast",S14="Korea DPR",S14="China PR",S14="IR Iran",S14="Türkiye",S14="Congo DR",S14="German DR",ISNUMBER(SEARCH("rn"">United Arab Emirates",S14)),ISNUMBER(SEARCH("rn"">Republic of Ireland",S14)),ISNUMBER(SEARCH("rn"">Bosnia and Herzegovina",S14)),ISNUMBER(SEARCH("rn"">Trinidad and Tobago",S14)),ISNUMBER(SEARCH("rn"">Serbia and Montenegro",S14)),ISNUMBER(SEARCH(_xlfn.UNICHAR(65533),S14))),"RENOMMER","-")) -> - | V14: {=_xlfn.IFS( ISNUMBER(SEARCH("USA",S14)),"United States", ISNUMBER(SEARCH("Republic of Korea",S14)),"South Korea", ISNUMBER(SEARCH("Cape Verde",S14)),"Cabo Verde", ISNUMBER(SEARCH("Czechia",S14)),"Czech Republic", ISNUMBER(SEARCH("Türkiye",S14)),"Turkey", ISNUMBER(SEARCH("Ivory Coast",S14)),"Côte d'Ivoire", ISNUMBER(SEARCH("Korea Republic",S14)),"South Korea", ISNUMBER(SEARCH("Germany FR",S14)),"FR Germany", ISNUMBER(SEARCH("Germany DR",S14)),"DR Germany", ISNUMBER(SEARCH("Korea DPR",S14)),"North Korea", ISNUMBER(SEARCH("China PR",S14)),"China", ISNUMBER(SEARCH("IR Iran",S14)),"Iran", ISNUMBER(SEARCH("Congo DR",S14)),"Democratic Republic of the Congo", ISNUMBER(SEARCH("DR Congo",S14)),"Democratic Republic of the Congo", ISNUMBER(SEARCH("German DR",S14)),"DR Germany", ISNUMBER(SEARCH("rn"">United Arab Emirates",S14)),"United Arab Emirates", ISNUMBER(SEARCH("rn"">Republic of Ireland",S14)),"Ireland", ISNUMBER(SEARCH("rn"">Bosnia and Herzegovina",S14)),"Bosnia and Herzegovina", ISNUMBER(SEARCH("rn"">Trinidad and Tobago",S14)),"Trinidad and Tobago", ISNUMBER(SEARCH("rn"">Serbia and Montenegro",S14)),"Serbia and Montenegro", ISNUMBER(SEARCH("te d'Ivoire",S14)),"Côte d'Ivoire", TRUE,"" )} | W14: =IF(V14="",S14,V14) -> Argentina | X14: Angola | Z14: Dataset : 2026 Squads | AA14: name | AB14: {=_xlfn._xlws.FILTER(DATA_BRUT!U2:AA1250,ISNUMBER(SEARCH(_xlfn.UNICHAR(65533),DATA_BRUT!V2:V1250)),"Aucuns caractères spéciaux détectés")} -> Aucuns caractères spéciaux détectés | AD14: Correction | AE14: NON | AF14: OUI | AG14: =IF(AG13=FALSE,"OUI","NON") -> NON | AH14: =IF(AH13=FALSE,"OUI","NON") -> NON | AI14: =IF(AI13=FALSE,"OUI","NON") -> NON | AS14: First round | AT14: GROUP_STAGE | AU14: 6 | AV14: SEMI_FINALS | AW14: GROUP_STAGE | AY14: {=INDEX(_xlfn.UNIQUE(DATA_CLEANED!AF5:'DATA_CLEANED'!AF1062),INT((ROWS(AY$12:AY14)-1)/3)+1)} -> 1930 | AZ14: FINAL | BA14: 1 | BB14: =COUNTIFS(DATA_CLEANED!AH$3:AH$1060,AZ14,DATA_CLEANED!AF$3:AF$1060,AY14) -> 1 | BC14: =IF(BA14>BB14,"Donnée manquante",IF(BA14<BB14,"A VERIFIER","OK")) -> OK | BE14: =IF(OR(DATA_CLEANED!AL5="",DATA_CLEANED!AM5=""),"MANQUANT",IF(OR(NOT(ISNUMBER(DATA_CLEANED!AL5)),NOT(ISNUMBER(DATA_CLEANED!AM5))),"ENTREE INVALIDE",IF(OR(DATA_CLEANED!AL5<0,DATA_CLEANED!AM5<0),"SCORE NEGATIF","OK"))) -> OK | BF14: =IF(DATA_CLEANED!AK5<>DATA_CLEANED!AN5,"OK","ERREUR") -> OK | BG14: =IF(DATA_CLEANED!AL5>DATA_CLEANED!AM5,DATA_CLEANED!AK5,IF(AND(DATA_QUALITE!W4491="-",DATA_CLEANED!AM5=DATA_CLEANED!AL5),"MATCH NUL",IF(AND(DATA_QUALITE!V4491="-",DATA_QUALITE!U4491="AUCUNE"),DATA_QUALITE!T4491,IF(DATA_QUALITE!V4491<>"-",DATA_QUALITE!V4491,DATA_CLEANED!AN5)))) -> Yugoslavia | BH14: =IF(AND(BG14="MATCH NUL",DATA_CLEANED!AO5="-"),"MATCH_NUL",IF(ISNUMBER(SEARCH("win on penalties",W4491)),"WIN_BY_PENALTY",IF(ISNUMBER(SEARCH("win after extra time",W4491)),"WIN_BY_EXTRA_TIME",IF(ISNUMBER(SEARCH("Golden Goal",W4491)),"WIN_BY_GOLDEN_GOAL","WIN_BY_SCORE")))) -> WIN_BY_SCORE | BI14: =IF(OR(BG14=DATA_CLEANED!AK5,BG14=DATA_CLEANED!AN5,BG14="MATCH NUL"),"OK","ERREUR") -> OK | BK14: 1938 | BL14: 18 | BM14: 18 | BN14: =IF(BL14=BM14,"OK","MATCH_MANQUANTS") -> OK
B15: =UPPER("retiré") -> RETIRÉ | C15: 2014.0 | D15: 29 Jun 2014 - 17:00 | E15: Round of 16 | F15: Arena Pernambuco | G15: Recife | H15: Costa Rica | I15: 1.0 | J15: 1.0 | K15: Greece | L15: Costa Rica win on penalties (5 - 3) | M15: 2014.0|29 Jun 2014 - 17:00 |Round of 16|Arena Pernambuco|Recife |Costa Rica|1.0|1.0|Greece|Costa Rica win on penalties (5 - 3) | N15: DOUBLON | R15: Algeria | S15: France | T15: =IF(COUNTIF(R$13:R$250,S15)=1,"OK","ERREUR") -> OK | U15: =IF(OR(S15="Scotland",S15="England",S15="Wales",S15="Yugoslavia",S15="Czechoslovakia",S15="Northern Ireland",S15="Soviet Union",S15="Zaire",S15="Dutch East Indies"),"AUCUNE",IF(OR(S15="Cape Verde",S15="USA",S15="DR Congo",S15="Republic of Korea",S15="Germany FR",S15="Germany DR",S15="Czechia",S15="Ivory Coast",S15="Korea DPR",S15="China PR",S15="IR Iran",S15="Türkiye",S15="Congo DR",S15="German DR",ISNUMBER(SEARCH("rn"">United Arab Emirates",S15)),ISNUMBER(SEARCH("rn"">Republic of Ireland",S15)),ISNUMBER(SEARCH("rn"">Bosnia and Herzegovina",S15)),ISNUMBER(SEARCH("rn"">Trinidad and Tobago",S15)),ISNUMBER(SEARCH("rn"">Serbia and Montenegro",S15)),ISNUMBER(SEARCH(_xlfn.UNICHAR(65533),S15))),"RENOMMER","-")) -> - | V15: {=_xlfn.IFS( ISNUMBER(SEARCH("USA",S15)),"United States", ISNUMBER(SEARCH("Republic of Korea",S15)),"South Korea", ISNUMBER(SEARCH("Cape Verde",S15)),"Cabo Verde", ISNUMBER(SEARCH("Czechia",S15)),"Czech Republic", ISNUMBER(SEARCH("Türkiye",S15)),"Turkey", ISNUMBER(SEARCH("Ivory Coast",S15)),"Côte d'Ivoire", ISNUMBER(SEARCH("Korea Republic",S15)),"South Korea", ISNUMBER(SEARCH("Germany FR",S15)),"FR Germany", ISNUMBER(SEARCH("Germany DR",S15)),"DR Germany", ISNUMBER(SEARCH("Korea DPR",S15)),"North Korea", ISNUMBER(SEARCH("China PR",S15)),"China", ISNUMBER(SEARCH("IR Iran",S15)),"Iran", ISNUMBER(SEARCH("Congo DR",S15)),"Democratic Republic of the Congo", ISNUMBER(SEARCH("DR Congo",S15)),"Democratic Republic of the Congo", ISNUMBER(SEARCH("German DR",S15)),"DR Germany", ISNUMBER(SEARCH("rn"">United Arab Emirates",S15)),"United Arab Emirates", ISNUMBER(SEARCH("rn"">Republic of Ireland",S15)),"Ireland", ISNUMBER(SEARCH("rn"">Bosnia and Herzegovina",S15)),"Bosnia and Herzegovina", ISNUMBER(SEARCH("rn"">Trinidad and Tobago",S15)),"Trinidad and Tobago", ISNUMBER(SEARCH("rn"">Serbia and Montenegro",S15)),"Serbia and Montenegro", ISNUMBER(SEARCH("te d'Ivoire",S15)),"Côte d'Ivoire", TRUE,"" )} | W15: =IF(V15="",S15,V15) -> France | X15: Argentina | AA15: club | AB15: {=_xlfn._xlws.FILTER(DATA_BRUT!U2:AA1250,ISNUMBER(SEARCH(_xlfn.UNICHAR(65533),DATA_BRUT!Z2:Z1250)),"Aucuns caractères spéciaux détectés")} -> Aucuns caractères spéciaux détectés | AD15: Colonne corrigée | AE15: =IF(AE14="NON","-","") -> - | AF15: {=VALUE(SUBSTITUTE(DATA_BRUT!B3:B50,".",","))} -> 28.8 | AG15: =IF(AG14="NON","-","") -> - | AH15: =IF(AH14="NON","-","") -> - | AI15: =IF(AI14="NON","-","") -> - | AS15: Group 1 | AT15: GROUP_STAGE | AU15: 6 | AV15: SEMI_FINALS | AW15: GROUP_STAGE | AY15: {=INDEX(_xlfn.UNIQUE(DATA_CLEANED!AF6:'DATA_CLEANED'!AF1063),INT((ROWS(AY$12:AY15)-1)/3)+1)} -> 1934 | AZ15: QUARTER_FINALS | BA15: 5 | BB15: =COUNTIFS(DATA_CLEANED!AH$3:AH$1060,AZ15,DATA_CLEANED!AF$3:AF$1060,AY15) -> 5 | BC15: =IF(BA15>BB15,"Donnée manquante",IF(BA15<BB15,"A VERIFIER","OK")) -> OK | BE15: =IF(OR(DATA_CLEANED!AL6="",DATA_CLEANED!AM6=""),"MANQUANT",IF(OR(NOT(ISNUMBER(DATA_CLEANED!AL6)),NOT(ISNUMBER(DATA_CLEANED!AM6))),"ENTREE INVALIDE",IF(OR(DATA_CLEANED!AL6<0,DATA_CLEANED!AM6<0),"SCORE NEGATIF","OK"))) -> OK | BF15: =IF(DATA_CLEANED!AK6<>DATA_CLEANED!AN6,"OK","ERREUR") -> OK | BG15: =IF(DATA_CLEANED!AL6>DATA_CLEANED!AM6,DATA_CLEANED!AK6,IF(AND(DATA_QUALITE!W4492="-",DATA_CLEANED!AM6=DATA_CLEANED!AL6),"MATCH NUL",IF(AND(DATA_QUALITE!V4492="-",DATA_QUALITE!U4492="AUCUNE"),DATA_QUALITE!T4492,IF(DATA_QUALITE!V4492<>"-",DATA_QUALITE!V4492,DATA_CLEANED!AN6)))) -> Romania | BH15: =IF(AND(BG15="MATCH NUL",DATA_CLEANED!AO6="-"),"MATCH_NUL",IF(ISNUMBER(SEARCH("win on penalties",W4492)),"WIN_BY_PENALTY",IF(ISNUMBER(SEARCH("win after extra time",W4492)),"WIN_BY_EXTRA_TIME",IF(ISNUMBER(SEARCH("Golden Goal",W4492)),"WIN_BY_GOLDEN_GOAL","WIN_BY_SCORE")))) -> WIN_BY_SCORE | BI15: =IF(OR(BG15=DATA_CLEANED!AK6,BG15=DATA_CLEANED!AN6,BG15="MATCH NUL"),"OK","ERREUR") -> OK | BK15: 1950 | BL15: 22 | BM15: 22 | BN15: =IF(BL15=BM15,"OK","MATCH_MANQUANTS") -> OK
B16: =UPPER("retiré") -> RETIRÉ | C16: 2014.0 | D16: 30 Jun 2014 - 13:00 | E16: Round of 16 | F16: Estadio Nacional | G16: Brasilia | H16: France | I16: 2.0 | J16: 0.0 | K16: Nigeria | M16: 2014.0|30 Jun 2014 - 13:00 |Round of 16|Estadio Nacional|Brasilia |France|2.0|0.0|Nigeria| | N16: DOUBLON | R16: American Samoa | S16: England | T16: =IF(COUNTIF(R$13:R$250,S16)=1,"OK","ERREUR") -> ERREUR | U16: =IF(OR(S16="Scotland",S16="England",S16="Wales",S16="Yugoslavia",S16="Czechoslovakia",S16="Northern Ireland",S16="Soviet Union",S16="Zaire",S16="Dutch East Indies"),"AUCUNE",IF(OR(S16="Cape Verde",S16="USA",S16="DR Congo",S16="Republic of Korea",S16="Germany FR",S16="Germany DR",S16="Czechia",S16="Ivory Coast",S16="Korea DPR",S16="China PR",S16="IR Iran",S16="Türkiye",S16="Congo DR",S16="German DR",ISNUMBER(SEARCH("rn"">United Arab Emirates",S16)),ISNUMBER(SEARCH("rn"">Republic of Ireland",S16)),ISNUMBER(SEARCH("rn"">Bosnia and Herzegovina",S16)),ISNUMBER(SEARCH("rn"">Trinidad and Tobago",S16)),ISNUMBER(SEARCH("rn"">Serbia and Montenegro",S16)),ISNUMBER(SEARCH(_xlfn.UNICHAR(65533),S16))),"RENOMMER","-")) -> AUCUNE | V16: {=_xlfn.IFS( ISNUMBER(SEARCH("USA",S16)),"United States", ISNUMBER(SEARCH("Republic of Korea",S16)),"South Korea", ISNUMBER(SEARCH("Cape Verde",S16)),"Cabo Verde", ISNUMBER(SEARCH("Czechia",S16)),"Czech Republic", ISNUMBER(SEARCH("Türkiye",S16)),"Turkey", ISNUMBER(SEARCH("Ivory Coast",S16)),"Côte d'Ivoire", ISNUMBER(SEARCH("Korea Republic",S16)),"South Korea", ISNUMBER(SEARCH("Germany FR",S16)),"FR Germany", ISNUMBER(SEARCH("Germany DR",S16)),"DR Germany", ISNUMBER(SEARCH("Korea DPR",S16)),"North Korea", ISNUMBER(SEARCH("China PR",S16)),"China", ISNUMBER(SEARCH("IR Iran",S16)),"Iran", ISNUMBER(SEARCH("Congo DR",S16)),"Democratic Republic of the Congo", ISNUMBER(SEARCH("DR Congo",S16)),"Democratic Republic of the Congo", ISNUMBER(SEARCH("German DR",S16)),"DR Germany", ISNUMBER(SEARCH("rn"">United Arab Emirates",S16)),"United Arab Emirates", ISNUMBER(SEARCH("rn"">Republic of Ireland",S16)),"Ireland", ISNUMBER(SEARCH("rn"">Bosnia and Herzegovina",S16)),"Bosnia and Herzegovina", ISNUMBER(SEARCH("rn"">Trinidad and Tobago",S16)),"Trinidad and Tobago", ISNUMBER(SEARCH("rn"">Serbia and Montenegro",S16)),"Serbia and Montenegro", ISNUMBER(SEARCH("te d'Ivoire",S16)),"Côte d'Ivoire", TRUE,"" )} | W16: =IF(V16="",S16,V16) -> England | X16: Australia | Z16: Dataset : Matches (1930-2026) | AA16: Stadium | AB16: {=_xlfn.UNIQUE(_xlfn._xlws.FILTER(DATA_BRUT!AF2:AF1076,ISNUMBER(SEARCH(_xlfn.UNICHAR(65533),DATA_BRUT!AF2:AF1076)),"Aucuns caractères spéciaux détectés"))} -> Stade V�lodrome | AF16: 28.7 | AS16: Group 2 | AT16: GROUP_STAGE | AU16: 6 | AV16: SEMI_FINALS | AW16: GROUP_STAGE | AY16: {=INDEX(_xlfn.UNIQUE(DATA_CLEANED!AF7:'DATA_CLEANED'!AF1064),INT((ROWS(AY$12:AY16)-1)/3)+1)} -> 1934 | AZ16: SEMI_FINALS | BA16: {=INDEX($BA$12:$BA$14,MOD(ROWS($BA$15:BA16)-1,3)+1)} -> 2 | BB16: =COUNTIFS(DATA_CLEANED!AH$3:AH$1060,AZ16,DATA_CLEANED!AF$3:AF$1060,AY16) -> 2 | BC16: =IF(BA16>BB16,"Donnée manquante",IF(BA16<BB16,"A VERIFIER","OK")) -> OK | BE16: =IF(OR(DATA_CLEANED!AL7="",DATA_CLEANED!AM7=""),"MANQUANT",IF(OR(NOT(ISNUMBER(DATA_CLEANED!AL7)),NOT(ISNUMBER(DATA_CLEANED!AM7))),"ENTREE INVALIDE",IF(OR(DATA_CLEANED!AL7<0,DATA_CLEANED!AM7<0),"SCORE NEGATIF","OK"))) -> OK | BF16: =IF(DATA_CLEANED!AK7<>DATA_CLEANED!AN7,"OK","ERREUR") -> OK | BG16: =IF(DATA_CLEANED!AL7>DATA_CLEANED!AM7,DATA_CLEANED!AK7,IF(AND(DATA_QUALITE!W4493="-",DATA_CLEANED!AM7=DATA_CLEANED!AL7),"MATCH NUL",IF(AND(DATA_QUALITE!V4493="-",DATA_QUALITE!U4493="AUCUNE"),DATA_QUALITE!T4493,IF(DATA_QUALITE!V4493<>"-",DATA_QUALITE!V4493,DATA_CLEANED!AN7)))) -> Argentina | BH16: =IF(AND(BG16="MATCH NUL",DATA_CLEANED!AO7="-"),"MATCH_NUL",IF(ISNUMBER(SEARCH("win on penalties",W4493)),"WIN_BY_PENALTY",IF(ISNUMBER(SEARCH("win after extra time",W4493)),"WIN_BY_EXTRA_TIME",IF(ISNUMBER(SEARCH("Golden Goal",W4493)),"WIN_BY_GOLDEN_GOAL","WIN_BY_SCORE")))) -> WIN_BY_SCORE | BI16: =IF(OR(BG16=DATA_CLEANED!AK7,BG16=DATA_CLEANED!AN7,BG16="MATCH NUL"),"OK","ERREUR") -> OK | BK16: 1954 | BL16: 26 | BM16: 26 | BN16: =IF(BL16=BM16,"OK","MATCH_MANQUANTS") -> OK
